Workbook

Sheet 1 месяц
A2: Размещение вакансии | B2: хх.ру | C2: 1000
A3: Размещение вакансии | B3: работу.ру | C3: 1500
A4: Размещение вакансии | B4: работу.ру | C4: 1500
A5: Оплата телефонии | C5: 15000
A6: Размещение вакансии | B6: работу.ру | C6: 1500
A7: Размещение вакансии | B7: работу.ру | C7: 1500
A8: Размещение вакансии | B8: работу.ру | C8: 1500
A9: Размещение вакансии | B9: работу.ру | C9: 1500
A10: Размещение вакансии | B10: хх.ру | C10: 5000
A11: Интеграция рабочих порталов к срм | C11: 15000
A12: Размещение вакансии | B12: хх.ру | C12: 5000
A13: Размещение вакансии | B13: хх.ру | C13: 11000
A14: Размещение вакансии | B14: работу.ру | C14: 2800
A15: Размещение вакансии | B15: хх.ру | C15: 5000
A16: Размещение вакансии | B16: хх.ру | C16: 5000
A17: Размещение вакансии | B17: хх.ру | C17: 5000
A18: Оплата IT-специалиста | C18: 20000
A19: Размещение вакансии | B19: хх.ру | C19: 5000
A20: Размещение вакансии | B20: хх.ру | C20: 5000
A21: Размещение вакансии | B21: хх.ру | C21: 5000
A22: Размещение вакансии | B22: хх.ру | C22: 5000
A23: Размещение вакансии | B23: хх.ру | C23: 5000
A24: Размещение вакансии | B24: авито | C24: 30000
A25: Размещение вакансии | B25: хх.ру | C25: 1500
A26: Размещение вакансии | B26: хх.ру | C26: 1500
A27: Размещение вакансии | B27: хх.ру | C27: 5000
A28: Оплата срм на месяц | C28: 6000
A29: Размещение вакансии | B29: хх.ру | C29: 5000
A30: Размещение вакансии | B30: хх.ру | C30: 1759
A31: Размещение вакансии | B31: авито | C31: 1000
A32: Размещение вакансии | B32: хх.ру | C32: 1500
A33: Размещение вакансии | B33: хх.ру | C33: 1500
A34: Размещение вакансии | B34: хх.ру | C34: 5000
A35: Размещение вакансии | B35: хх.ру | C35: 5000
A36: Рекрутер зп с проекта | C36: 75000
A37: Оплата маркетолога | C37: 15000
A38: Оплата сервера | C38: 3000
A40: Выручка по проекту | B40: 420000

Sheet 2 месяц
A1: Размещение вакансии | B1: хх.ру | C1: 1000
A2: Размещение вакансии | B2: работу.ру | C2: 1500
A3: Размещение вакансии | B3: работу.ру | C3: 1500
A4: Размещение вакансии | B4: хх.ру | C4: 5000
A5: Размещение вакансии | B5: хх.ру | C5: 5000
A6: Интеграция рабочих порталов к срм | C6: 15000
A7: Размещение вакансии | B7: хх.ру | C7: 5000
A8: Размещение вакансии | B8: хх.ру | C8: 5000
A9: Размещение вакансии | B9: хх.ру | C9: 5000
A10: Размещение вакансии | B10: хх.ру | C10: 5000
A11: Размещение вакансии | B11: авито | C11: 30000
A12: Размещение вакансии | B12: хх.ру | C12: 1500
A13: Размещение вакансии | B13: хх.ру | C13: 1500
A14: Размещение вакансии | B14: хх.ру | C14: 5000
A15: Оплата срм | C15: 6000
A16: Размещение вакансии | B16: хх.ру | C16: 5000
A17: Размещение вакансии | B17: хх.ру | C17: 5000
A18: Размещение вакансии | B18: хх.ру | C18: 5000
A19: Размещение вакансии | B19: хх.ру | C19: 5000
A20: Размещение вакансии | B20: хх.ру | C20: 5000
A21: Оплата нейробота | C21: 22000
A22: Размещение вакансии | B22: хх.ру | C22: 5000
A23: Размещение вакансии | B23: хх.ру | C23: 1000
A24: Размещение вакансии | B24: работу.ру | C24: 1500
A25: Размещение вакансии | B25: работу.ру | C25: 1500
A26: Размещение вакансии | B26: работу.ру | C26: 1500
A27: Размещение вакансии | B27: работу.ру | C27: 1500
A28: Размещение вакансии | B28: работу.ру | C28: 1500
A29: Размещение вакансии | B29: работу.ру | C29: 1500
A30: Размещение вакансии | B30: хх.ру | C30: 5000
A31: Размещение вакансии | B31: хх.ру | C31: 5000
A32: Размещение вакансии | B32: хх.ру | C32: 11000
A33: Размещение вакансии | B33: работу.ру | C33: 2800
A34: IT специалист зп с проекта | C34: 20000
A35: Размещение вакансии | B35: хх.ру | C35: 5000
A36: Размещение вакансии | B36: хх.ру | C36: 5000
A37: Размещение вакансии | B37: хх.ру | C37: 5000
A38: Размещение вакансии | B38: хх.ру | C38: 5000
A39: Размещение вакансии | B39: хх.ру | C39: 5000
A40: Размещение вакансии | B40: хх.ру | C40: 5000
...

Sheet Модель
C2: Категории расходов | D2: 1 месяц | E2: 2 месяц | F2: Итог
C3: 1. З/п и выплаты
C4: Рекрутер | D4: ='1 месяц'!C36 -> 75000 | E4: ='2 месяц'!C41 -> 30000 | F4: =SUM(D4:E4) -> 105000
C5: IT- специалист | D5: ='1 месяц'!C18 -> 20000 | E5: ='2 месяц'!C34 -> 20000 | F5: =SUM(D5:E5) -> 40000
C6: Маркетолог | D6: ='1 месяц'!C37 -> 15000 | E6: ='2 месяц'!C47 -> 15000 | F6: =SUM(D6:E6) -> 30000
C7: Итого | D7: =SUM(D4:D6) -> 110000 | E7: =SUM(E4:E6) -> 65000 | F7: =SUM(F4:F6) -> 175000 | H7: Стоит исследовать эффективность площадок вакансий, рассмотреть необходимость нейробота, есть смысл рассмотреть сдельную оплату рекрутера.
C8: 2. Размещение вакансия | H8: Резервы можно найти в снижении расходов на размещение вакансий на 10%, экономия около 36тр в целом, поискать альтернативные CRM.
C9: хх.ру | D9: =SUM('1 месяц'!C2,'1 месяц'!C10,'1 месяц'!C12:C13,'1 месяц'!C15:C17,'1 месяц'!C19:C23,'1 месяц'!C25:C27,'1 месяц'!C29:C30,'1 месяц'!C32:C35) -> 89759 | E9: =SUM('2 месяц'!C1,'2 месяц'!C4:C5,'2 месяц'!C7:C10,'2 месяц'!C12:C14,'2 месяц'!C16:C20,'2 месяц'!C22:C23,'2 месяц'!C30:C32,'2 месяц'!C35:C40,'2 месяц'!C42:C43,'2 месяц'!C45:C46,'2 месяц'!C48:C50,'2 месяц'!C52:C55) -> 158759 | F9: =SUM(D9:E9) -> 248518
C10: работу.ру | D10: =SUM('1 месяц'!C3:C4,'1 месяц'!C6:C9,'1 месяц'!C14) -> 11800 | E10: =SUM('2 месяц'!C2:C3,'2 месяц'!C24:C29,'2 месяц'!C33) -> 14800 | F10: =SUM(D10:E10) -> 26600
C11: авито | D11: ='1 месяц'!C31+'1 месяц'!C24 -> 31000 | E11: =SUM('2 месяц'!C11,'2 месяц'!C44,'2 месяц'!C51) -> 61000 | F11: =SUM(D11:E11) -> 92000
C12: Итого | D12: =SUM(D9:D11) -> 132559 | E12: =SUM(E9:E11) -> 234559 | F12: =SUM(F9:F11) -> 367118
C13: 3. IT и инфраструктура
C14: Интеграция рабочих порталов к срм | D14: ='1 месяц'!C11 -> 15000 | E14: ='2 месяц'!C6 -> 15000 | F14: =SUM(D14:E14) -> 30000
C15: Оплата срм на месяц | D15: ='1 месяц'!C28 -> 6000 | E15: ='2 месяц'!C15 -> 6000 | F15: =SUM(D15:E15) -> 12000
C16: Оплата сервера | D16: ='1 месяц'!C38 -> 3000 | E16: ='2 месяц'!C56 -> 6000 | F16: =SUM(D16:E16) -> 9000
C17: Нейробот | E17: ='2 месяц'!C21 -> 22000 | F17: =SUM(D17:E17) -> 22000
C18: Итого | D18: =SUM(D14:D17) -> 24000 | E18: =SUM(E14:E17) -> 49000 | F18: =SUM(F14:F17) -> 73000
C19: 4. Прочие расходы
C20: Оплата телефонии | D20: ='1 месяц'!C5 -> 15000 | F20: =SUM(D20:E20) -> 15000
C21: Итого | D21: =SUM(D20) -> 15000 | E21: =SUM(E20) -> 0 | F21: =SUM(F20) -> 15000
C22: Всего расходов | D22: =SUM(D7,D12,D18,D21) -> 281559 | E22: =SUM(E7,E12,E18,E21) -> 348559 | F22: =SUM(F7,F12,F18,F21) -> 630118
C23: Выручка по проекту | D23: ='1 месяц'!B40 -> 420000 | E23: ='2 месяц'!B58 -> 510000 | F23: =SUM(D23:E23) -> 930000
C24: Прибыль | D24: =D23-D22 -> 138441 | E24: =E23-E22 -> 161441 | F24: =F23-F22 -> 299882
C25: Рентабельность | D25: =D24/D23 -> 0.32962143 | E25: =E24/E23 -> 0.31655098 | F25: =F24/F23 -> 0.32245376
